Workbook

Sheet دليل الاستخدام
A1: 📘 دليل الاستخدام الكامل — نظام Hormozi للتسويق الأوتوماتيكي
A2: تأليف النظام: جاسم محمد | كل لوحة = خطوة في رحلة تحويل المتابع إلى عميل يدفع تلقائياً
A5: 🗂️ فهرس النظام — 7 لوحات تعمل معاً تلقائياً
A6: رقم | B6: اسم اللوحة | C6: دورها في النظام | D6: متى تفتحها؟ | E6: ما تكتب فيها؟
A7: 1 | B7: 🏠 لوحة التحكم | C7: داشبورد يعرض جميع مؤشرات الأداء دفعة واحدة | D7: يومياً — أول شيء بالصباح | E7: لا شيء — تتحدّث تلقائياً
A8: 2 | B8: 💰 بناء العرض الضارب | C8: تصميم عرضك حتى يشعر العميل بالغباء إذا رفض | D8: مرة واحدة — ثم تحديث كل دفعة | E8: اسم منتجك + سعره + ضمانك
A9: 3 | B9: 🧲 توليد العملاء | C9: كيف تجذب عملاء محتملين بالطرق الأربعة | D9: أسبوعياً | E9: نوع Lead Magnet الذي ستستخدمه
A10: 4 | B10: 📉 قمع المبيعات | C10: رحلة العميل من الوعي حتى الشراء وما بعده | D10: مستمر — مرجع دائم | E10: لا شيء — مرجعية ثابتة
A11: 5 | B11: ✉️ تسلسل الرسائل | C11: ManyChat + بريد + WhatsApp تعمل 24/7 | D11: مرة واحدة ثم تشتغل أوتوماتيكياً | E11: نصوص الرسائل بنبرتك
A12: 6 | B12: ⚙️ إعدادات الأتمتة | C12: ManyChat + Zapier تربط كل المنصات ببعضها | D12: مرة واحدة — تشغيل مستمر | E12: حسابات ManyChat + Zapier + بريد
A13: 7 | B13: 📈 متابعة الأداء | C13: قياس النتائج وتحديث الأهداف | D13: أسبوعياً / شهرياً | E13: الهدف والنتيجة الفعلية فقط
A16: 💰 اللوحة 1: بناء العرض الضارب
A17: الهدف: تحويل منتجك إلى عرض يجعل العميل يشعر بالغباء إذا رفض — مبدأ Alex Hormozi
A19: الجزء الأول: معادلة القيمة — خانات D و E
A20: العمود | B20: ماذا تكتب؟ | C20: مثال (بالأزرق) | D20: نصيحة
A21: D — تقييمك (1-10) | B21: كيف تقيّم عرضك في كل عنصر من المعادلة | C21: أكتب رقم بين 1-10 — مثال: 8 | D21: أي عنصر أقل من 7 = ضعف يجب تعالجه فوراً
A22: E — خطة التحسين | B22: كيف سترفع هذا العنصر في عرضك | C22: أضيف ضمان 30 يوم + أظهر شهادة عميل بأرقام محددة | D22: الضمان أقوى أداة لرفع تقييم احتمالية النجاح
A24: الجزء الثاني: بناء العرض خطوة بخطوة — عمود D فقط
A25: الخطوة | B25: السؤال | C25: مثال جاسم محمد (بالأزرق)
A26: 1 — المشكلة | B26: ما الألم الأكبر لجمهورك؟ | C26: يملكون مهارات قيمة لكن لا أحد يشتري منهم — ينشرون بلا نتيجة
A27: 2 — الحلم | B27: ما الذي يحلم به عميلك؟ | C27: 10,000 ريال شهرياً من محتوى يبيعه على السوشيال بدون إعلانات
A28: 3 — المنتج | B28: ما اسم ووصف كورسك؟ | C28: كورس 'نظام العميل الأوتوماتيكي' — 8 أسابيع تحول متابعك لمشتري
A29: 4 — العقبات | B29: لماذا لا يشتري العميل الآن؟ | C29: ما عنديش وقت | خايف من التكنولوجيا | جربت وما نجحت | لا أعرف من أين أبدأ
A30: 5 — الحلول | B30: كيف تحل كل عقبة؟ | C30: وحدة 1: محتوى في 60 دقيقة | وحدة 2: ManyChat بدون خبرة | وحدة 3: إغلاق البيع
A31: 6 — البونصات | B31: ما الهدايا المجانية مع العرض؟ | C31: 30 قالب ريلز + مجتمع Telegram + جلسة مراجعة بقيمة 297ر مجاناً
A32: 7 — الضمان | B32: كيف تعكس المخاطرة؟ | C32: أمارس معك حتى تحصل على أول عميل مدفوع — أو أرد كامل المبلغ
A33: 8 — الاستعجال | B33: لماذا يشتري الآن؟ | C33: الدفعة تفتح 1 رمضان — من يسجل اليوم يأخذ 497 بدل 697 ريال
A34: 9 — الندرة | B34: ما المحدودية الحقيقية؟ | C34: فقط 20 مقعد — 10 تبقت فقط
A37: 🧲 اللوحة 3: توليد العملاء المحتملين
A38: الهدف: جذب أشخاص مهتمين بمنتجك وجمع بياناتهم تلقائياً
A40: القسم الأول: الطرق الأربعة (Core Four) — عمود G (الحالة)
A41: الطريقة | B41: ماذا تفعل؟ | C41: مثال (بالأزرق) | D41: حدد حالتها بعد التنفيذ
A42: 1 — تواصل دافئ | B42: ابدأ بقائمة 100 شخص تعرفهم — أرسل رسالة مخصصة لكل واحد | C42: مرحبا أحمد! أنا أبني نظام تسويق أوتوماتيكي — هل تعرف أحد يبحث عن زيادة مبيعاته؟ | D42: تغيير → ✅ بعد التنفيذ
A43: 2 — محتوى مجاني | B43: 3-5 منشورات/أسبوع تحل مشكلة واحدة في كل منشور | C43: Reel: '3 أخطاء تقتل حسابك على انستغرام وأنت تعرفها ما' | D43: تغيير → ✅ بعد التنفيذ
A44: 3 — تواصل بارد | B44: 100 رسالة DM يومياً لحسابات ترفع محتوى في مجالك | C44: أحببت محتواك! عندي كتاب مجاني يصلح لجمهورك — تبيه؟ | D44: تغيير → ✅ بعد التنفيذ
A46: القسم الثاني: Lead Magnets — عمود B (العنوان) + C (الوصف) + D (طريقة التسليم)
A47: نوع الهدية | B47: العنوان | C47: طريقة التسليم (بالأزرق)
A48: كتاب PDF | B48: 7 أخطاء تقتل حسابك على انستغرام | C48: شخص يعلق 'كتاب' على ريلز → ManyChat يرسله فوراً في DM
A49: ويبينار | B49: كيف تحول متابعيك لعملاء خلال جلسة واحدة | C49: صفحة تسجيل → Zoom مباشر → عرض في النهاية
A52: ✉️ اللوحة 5: تسلسل الرسائل
...

Sheet لوحة التحكم
A1: 📊 لوحة التحكم الرئيسية — نظام Hormozi للتسويق الأوتوماتيكي
A2: نظرة شاملة على أداء جميع قنوات التسويق والمبيعات — يتم التحديث تلقائياً من ورقة متابعة الأداء
A4: 📈 ملخص مؤشرات الأداء الرئيسية — مقسّم حسب القنوات
A5: 📱 السوشيال ميديا | B5: القيمة | C5: 🌐 الموقع الإلكتروني | D5: القيمة | E5: 📧 البريد الإلكتروني | F5: القيمة | G5: 💰 المبيعات والإيرادات | H5: القيمة
A6: ✅ مؤشرات محققة (≥100%) | B6: =COUNTIF('متابعة الأداء'!D5:D12,">="&1) -> 5 | C6: ✅ مؤشرات محققة (≥100%) | D6: =COUNTIF('متابعة الأداء'!D16:D22,">="&1) -> 2 | E6: ✅ مؤشرات محققة (≥100%) | F6: =COUNTIF('متابعة الأداء'!D26:D32,">="&1) -> 3 | G6: ✅ مؤشرات محققة (≥100%) | H6: =COUNTIF('متابعة الأداء'!D36:D43,">="&1) -> 2
A7: ❌ مؤشرات أقل من الهدف | B7: =COUNTIFS('متابعة الأداء'!D5:D12,"<"&1,'متابعة الأداء'!D5:D12,"<>") -> 3 | C7: ❌ مؤشرات أقل من الهدف | D7: =COUNTIFS('متابعة الأداء'!D16:D22,"<"&1,'متابعة الأداء'!D16:D22,"<>") -> 5 | E7: ❌ مؤشرات أقل من الهدف | F7: =COUNTIFS('متابعة الأداء'!D26:D32,"<"&1,'متابعة الأداء'!D26:D32,"<>") -> 4 | G7: ❌ مؤشرات أقل من الهدف | H7: =COUNTIFS('متابعة الأداء'!D36:D43,"<"&1,'متابعة الأداء'!D36:D43,"<>") -> 6
A8: 📊 متوسط نسبة التحقيق | B8: =IFERROR(AVERAGEIF('متابعة الأداء'!D5:D12,"<>",'متابعة الأداء'!D5:D12),0) -> 1.1242708 | C8: 📊 متوسط نسبة التحقيق | D8: =IFERROR(AVERAGEIF('متابعة الأداء'!D16:D22,"<>",'متابعة الأداء'!D16:D22),0) -> 0.92446803 | E8: 📊 متوسط نسبة التحقيق | F8: =IFERROR(AVERAGEIF('متابعة الأداء'!D26:D32,"<>",'متابعة الأداء'!D26:D32),0) -> 0.97598095 | G8: 📊 متوسط نسبة التحقيق | H8: =IFERROR(AVERAGEIF('متابعة الأداء'!D36:D43,"<>",'متابعة الأداء'!D36:D43),0) -> 0.98609167
A10: 🏆 الأداء العام — ملخص شامل
A11: المقياس | B11: القيمة | C11: المقياس | D11: القيمة | E11: المقياس | F11: القيمة | G11: المقياس | H11: القيمة
A12: إجمالي المؤشرات المحققة | B12: =B6+D6+F6+H6 -> 12 | C12: إجمالي المؤشرات غير المحققة | D12: =B7+D7+F7+H7 -> 18 | E12: المتوسط العام للتحقيق | F12: =IFERROR(AVERAGEIF('متابعة الأداء'!D5:D43,"<>",'متابعة الأداء'!D5:D43),0) -> 1.0062014 | G12: التقييم العام | H12: =IF(F12>=1,"🟢 ممتاز",IF(F12>=0.7,"🟡 جيد",IF(F12>=0.5,"🟠 مقبول",IF(F12>0,"🔴 يحتاج تحسين","⚪ لا توجد بيانات")))) -> 🟢 ممتاز
A14: 📱 تفاصيل أداء السوشيال ميديا — مرتبط بـ متابعة الأداء
A15: المؤشر | B15: الهدف | C15: الفعلي | D15: نسبة التحقيق | E15: الحالة
A16: عدد المتابعين الجدد | B16: ='متابعة الأداء'!B5 -> 500 | C16: ='متابعة الأداء'!C5 -> 620 | D16: ='متابعة الأداء'!D5 -> 1.24 | E16: =IF('متابعة الأداء'!D5="","⚪",IF('متابعة الأداء'!D5>=1,"✅ محقق",IF('متابعة الأداء'!D5>=0.7,"⚠️ قريب","❌ أقل"))) -> ✅ محقق
A17: معدل التفاعل على المنشورات | B17: ='متابعة الأداء'!B6 -> 0.05 | C17: ='متابعة الأداء'!C6 -> 0.048 | D17: ='متابعة الأداء'!D6 -> 0.96 | E17: =IF('متابعة الأداء'!D6="","⚪",IF('متابعة الأداء'!D6>=1,"✅ محقق",IF('متابعة الأداء'!D6>=0.7,"⚠️ قريب","❌ أقل"))) -> ⚠️ قريب
A18: عدد الرسائل المباشرة الواردة | B18: ='متابعة الأداء'!B7 -> 80 | C18: ='متابعة الأداء'!C7 -> 95 | D18: ='متابعة الأداء'!D7 -> 1.1875 | E18: =IF('متابعة الأداء'!D7="","⚪",IF('متابعة الأداء'!D7>=1,"✅ محقق",IF('متابعة الأداء'!D7>=0.7,"⚠️ قريب","❌ أقل"))) -> ✅ محقق
A19: تكلفة اكتساب العميل المحتمل | B19: ='متابعة الأداء'!B11 -> 25 | C19: ='متابعة الأداء'!C11 -> 31 | D19: ='متابعة الأداء'!D11 -> 1.24 | E19: =IF('متابعة الأداء'!D11="","⚪",IF('متابعة الأداء'!D11>=1,"✅ محقق",IF('متابعة الأداء'!D11>=0.7,"⚠️ قريب","❌ أقل"))) -> ✅ محقق
A21: 🌐 تفاصيل أداء الموقع الإلكتروني
A22: المؤشر | B22: الهدف | C22: الفعلي | D22: نسبة التحقيق | E22: الحالة
A23: عدد زوار الموقع | B23: ='متابعة الأداء'!B16 -> 3000 | C23: ='متابعة الأداء'!C16 -> 2750 | D23: ='متابعة الأداء'!D16 -> 0.91666667 | E23: =IF('متابعة الأداء'!D16="","⚪",IF('متابعة الأداء'!D16>=1,"✅ محقق",IF('متابعة الأداء'!D16>=0.7,"⚠️ قريب","❌ أقل"))) -> ⚠️ قريب
A24: معدل التحويل من زائر لمسجل | B24: ='متابعة الأداء'!B19 -> 0.04 | C24: ='متابعة الأداء'!C19 -> 0.036 | D24: ='متابعة الأداء'!D19 -> 0.9 | E24: =IF('متابعة الأداء'!D19="","⚪",IF('متابعة الأداء'!D19>=1,"✅ محقق",IF('متابعة الأداء'!D19>=0.7,"⚠️ قريب","❌ أقل"))) -> ⚠️ قريب
A25: عدد النقرات على زر الشراء | B25: ='متابعة الأداء'!B21 -> 85 | C25: ='متابعة الأداء'!C21 -> 67 | D25: ='متابعة الأداء'!D21 -> 0.78823529 | E25: =IF('متابعة الأداء'!D21="","⚪",IF('متابعة الأداء'!D21>=1,"✅ محقق",IF('متابعة الأداء'!D21>=0.7,"⚠️ قريب","❌ أقل"))) -> ⚠️ قريب
A26: عدد عمليات الشراء المكتملة | B26: ='متابعة الأداء'!B22 -> 18 | C26: ='متابعة الأداء'!C22 -> 14 | D26: ='متابعة الأداء'!D22 -> 0.77777778 | E26: =IF('متابعة الأداء'!D22="","⚪",IF('متابعة الأداء'!D22>=1,"✅ محقق",IF('متابعة الأداء'!D22>=0.7,"⚠️ قريب","❌ أقل"))) -> ⚠️ قريب
A28: 📧 تفاصيل أداء البريد الإلكتروني
A29: المؤشر | B29: الهدف | C29: الفعلي | D29: نسبة التحقيق | E29: الحالة
A30: عدد المشتركين الجدد بالقائمة البريدية | B30: ='متابعة الأداء'!B26 -> 200 | C30: ='متابعة الأداء'!C26 -> 235 | D30: ='متابعة الأداء'!D26 -> 1.175 | E30: =IF('متابعة الأداء'!D26="","⚪",IF('متابعة الأداء'!D26>=1,"✅ محقق",IF('متابعة الأداء'!D26>=0.7,"⚠️ قريب","❌ أقل"))) -> ✅ محقق
A31: معدل فتح الرسائل البريدية | B31: ='متابعة الأداء'!B27 -> 0.25 | C31: ='متابعة الأداء'!C27 -> 0.28 | D31: ='متابعة الأداء'!D27 -> 1.12 | E31: =IF('متابعة الأداء'!D27="","⚪",IF('متابعة الأداء'!D27>=1,"✅ محقق",IF('متابعة الأداء'!D27>=0.7,"⚠️ قريب","❌ أقل"))) -> ✅ محقق
A32: معدل النقر داخل البريد | B32: ='متابعة الأداء'!B28 -> 0.04 | C32: ='متابعة الأداء'!C28 -> 0.035 | D32: ='متابعة الأداء'!D28 -> 0.875 | E32: =IF('متابعة الأداء'!D28="","⚪",IF('متابعة الأداء'!D28>=1,"✅ محقق",IF('متابعة الأداء'!D28>=0.7,"⚠️ قريب","❌ أقل"))) -> ⚠️ قريب
A33: معدل التحويل من بريد لشراء | B33: ='متابعة الأداء'!B31 -> 0.025 | C33: ='متابعة الأداء'!C31 -> 0.02 | D33: ='متابعة الأداء'!D31 -> 0.8 | E33: =IF('متابعة الأداء'!D31="","⚪",IF('متابعة الأداء'!D31>=1,"✅ محقق",IF('متابعة الأداء'!D31>=0.7,"⚠️ قريب","❌ أقل"))) -> ⚠️ قريب
A35: 💰 تفاصيل أداء المبيعات والإيرادات — مرتبط بـ متابعة الأداء
A36: المؤشر | B36: الهدف | C36: الفعلي | D36: نسبة التحقيق | E36: الحالة
A37: إجمالي الإيرادات الشهرية | B37: ='متابعة الأداء'!B36 -> 15000 | C37: ='متابعة الأداء'!C36 -> 13916 | D37: ='متابعة الأداء'!D36 -> 0.92773333 | E37: =IF(D37="","⚪",IF(D37>=1,"✅",IF(D37>=0.7,"⚠️","❌"))) -> ⚠️
A38: عدد المبيعات الجديدة | B38: ='متابعة الأداء'!B37 -> 30 | C38: ='متابعة الأداء'!C37 -> 28 | D38: ='متابعة الأداء'!D37 -> 0.93333333 | E38: =IF(D38="","⚪",IF(D38>=1,"✅",IF(D38>=0.7,"⚠️","❌"))) -> ⚠️
A39: متوسط قيمة الطلب الواحد | B39: ='متابعة الأداء'!B38 -> 497 | C39: ='متابعة الأداء'!C38 -> 497 | D39: ='متابعة الأداء'!D38 -> 1 | E39: =IF(D39="","⚪",IF(D39>=1,"✅",IF(D39>=0.7,"⚠️","❌"))) -> ✅
A40: معدل التحويل الكلي للقمع | B40: ='متابعة الأداء'!B39 -> 0.03 | C40: ='متابعة الأداء'!C39 -> 0.025 | D40: ='متابعة الأداء'!D39 -> 0.83333333 | E40: =IF(D40="","⚪",IF(D40>=1,"✅",IF(D40>=0.7,"⚠️","❌"))) -> ⚠️
A41: قيمة العميل مدى الحياة | B41: ='متابعة الأداء'!B40 -> 1200 | C41: ='متابعة الأداء'!C40 -> 950 | D41: ='متابعة الأداء'!D40 -> 0.79166667 | E41: =IF(D41="","⚪",IF(D41>=1,"✅",IF(D41>=0.7,"⚠️","❌"))) -> ⚠️
A42: عائد الاستثمار التسويقي | B42: ='متابعة الأداء'!B41 -> 3 | C42: ='متابعة الأداء'!C41 -> 5.958 | D42: ='متابعة الأداء'!D41 -> 1.986 | E42: =IF(D42="","⚪",IF(D42>=1,"✅",IF(D42>=0.7,"⚠️","❌"))) -> ✅
A44: 🔻 حالة قمع المبيعات — مراحل التحويل (مرتبط بـ قمع المبيعات)
A45: المرحلة | B45: الاسم | C45: الهدف | D45: نسبة التحويل المتوقعة | E45: KPI الرئيسي | F45: الأدوات
A46: 1️⃣ الوعي | B46: ='قمع المبيعات'!B5 -> Awareness (اكتشاف) | C46: ='قمع المبيعات'!C5 -> يعرف أنك موجود | D46: ='قمع المبيعات'!F5 -> 100% (القاعدة) | E46: ='قمع المبيعات'!G5 -> مشاهدات + وصول | F46: ='قمع المبيعات'!D5 -> Instagram Reels + Posts + Stories
A47: 2️⃣ الاهتمام | B47: ='قمع المبيعات'!B6 -> Interest (اهتمام) | C47: ='قمع المبيعات'!C6 -> يتابعك ويتفاعل | D47: ='قمع المبيعات'!F6 -> 30-50% | E47: ='قمع المبيعات'!G6 -> متابعين جدد + تفاعل | F47: ='قمع المبيعات'!D6 -> ManyChat + Instagram DM
...

Sheet بناء العرض الضارب
A1: 💰 بناء العرض الضارب — Grand Slam Offer Builder
A2: المبدأ: اجعل عرضك جيداً لدرجة أن العميل يشعر بالغباء إذا رفض — Alex Hormozi
A4: 📐 معادلة القيمة (Value Equation) — أساس كل عرض ناجح
A5: عنصر المعادلة | B5: الوصف | C5: مثال تطبيقي | D5: تقييمك (1-10) | E5: خطة التحسين
A6: 🎯 النتيجة المحققة (Dream Outcome) | B6: ما الذي سيحصل عليه العميل فعلياً؟ | C6: بناء نظام تسويقي يحقق 10 آلاف دولار شهرياً | D6: 9 | E6: أضيف شهادات عملاء بأرقام محددة: 'حقق أحمد 12,000 ريال في 45 يوم'
A7: 📈 احتمالية النجاح (Perceived Likelihood) | B7: ما مدى ثقة العميل بأنه سينجح؟ | C7: شهادات عملاء + خطة خطوة بخطوة + دعم مباشر | D7: 6 | E7: أضيف ضمان استرداد 30 يوم + أظهر نتائج العملاء السابقين بالأرقام
A8: ⏱️ تقليل الوقت (Time Delay) | B8: كم يحتاج العميل ليرى نتائج؟ | C8: أول عميل خلال 30 يوم + نتائج ملموسة خلال 90 يوم | D8: 8 | E8: أوضح أن أول نتيجة تجيها خلال 7 أيام من التطبيق — ليس 90 يوم
A9: 💪 تقليل الجهد (Effort & Sacrifice) | B9: كم جهد يحتاج العميل لتحقيق النتيجة؟ | C9: قوالب جاهزة + أتمتة + فيديوهات قصيرة مبسطة | D9: 5 | E9: أصنع قوالب جاهزة + فيديوهات أقل من 10 دقائق + شيت تطبيق يومي
A11: 📊 معادلة القيمة = (النتيجة المحققة × احتمالية النجاح) ÷ (الوقت × الجهد) — كلما زاد البسط وقل المقام، زادت قيمة عرضك
A13: 🏗️ بناء العرض الضارب — خطوة بخطوة
A14: الخطوة | B14: العنصر | C14: الوصف | D14: معظم أصحاب المشاريع لا يحصلون على عملاء بانتظام رغم جودة منتجهم — ينشرون بدون خطة وينتظرون الزبائن يجون | E14: أمثلة
A15: 1 | B15: حدد مشكلة كبيرة (Big Problem) | C15: اختر مشكلة يعاني منها جمهورك بشدة | D15: يحققون 10,000 ريال شهرياً من محتواهم دون الحاجة لإعلانات مدفوعة أو وسيط | E15: لا يعرفون كيف يبنون جمهور على السوشيال ميديا
A16: 2 | B16: حدد الحلم (Dream Outcome) | C16: ما الذي يتمنى جمهورك تحقيقه؟ | D16: كورس 'نظام العميل الأوتوماتيكي' — خطة من 8 أسابيع تحول متابعيك إلى عملاء يدفعون تلقائياً | E16: بناء قاعدة 10,000 متابع مهتم خلال 6 أشهر
A17: 3 | B17: اصنع Vehicle (وسيلة الحل) | C17: منتجك هو الوسيلة لتحقيق الحلم | D17: • ما عنديش وقت للمحتوى • التكنولوجيا معقدة • لا أعرف ماذا أنشر • خايف من التجاهل • جربت من قبل وما نجحت | E17: كورس: نظام بناء الجمهور الأوتوماتيكي
A18: 4 | B18: حدد العقبات (Obstacles) | C18: ما الذي يمنع العميل من تحقيق حلمه؟ | D18: وحدة 1: بناء محتوى يجذب في 60 دقيقة | وحدة 2: ManyChat بدون خبرة | وحدة 3: قمع مبيعات يحول متابعيك لمشترين | وحدة 4: إعداد البريد الإلكتروني الأوتوماتيكي | وحدة 5: إغلاق البيع والتحصيل | E18: لا وقت / لا خبرة / لا أدوات / خوف من التكنولوجيا
A19: 5 | B19: حول العقبات لحلول (Solutions) | C19: لكل عقبة حل = وحدة في منتجك | D19: بونص 1: حزمة قوالب ريلز جاهزة (30 قالب) | بونص 2: مجتمع خاص على Telegram — دعم مدى الحياة | بونص 3: جلسة مراجعة شخصية واحدة بقيمة 297 ريال (.مجاناً) | E19: وحدة 1: إعداد الحسابات - وحدة 2: المحتوى الجاهز
A20: 6 | B20: أضف Bonuses (مكافآت) | C20: إضافات مجانية تزيد القيمة المحسوسة | D20: ضمان نتيجة: أمارس معك خطوة بخطوة حتى تحصل على أول عميل مدفوع — أو أرد لك كامل المبلغ | E20: قوالب جاهزة + مجتمع خاص + جلسة استشارة
A21: 7 | B21: أضف Guarantee (ضمان) | C21: اعكس المخاطرة من العميل إليك | D21: الدفعة القادمة تفتح بتاريخ 1 رمضان — من يسجل اليوم يأخذ سعر 497 ريال بدل 697 | E21: ضمان 30 يوم استرداد كامل / ضمان النتيجة
A22: 8 | B22: حدد الاستعجال (Urgency) | C22: اخلق سبباً حقيقياً للشراء الآن | D22: فقط 20 مقعد في الدفعة القادمة — 10 مقاعد تبقت | E22: أول 50 مشترك فقط / ينتهي العرض خلال 48 ساعة
A23: 9 | B23: حدد الندرة (Scarcity) | C23: اجعل العرض محدوداً بشكل حقيقي | D23: حدد محدودية حقيقية في عرضك | E23: فقط 20 مقعد / نسخة محدودة مع دعم شخصي
A25: 🪜 سلم المنتجات (Value Ladder) — من المجاني إلى VIP
A26: المستوى | B26: نوع العرض | C26: المنتج | D26: السعر ($) | E26: الهدف | F26: مثال
A27: 1 — مجاني | B27: Lead Magnet (جذب) | C27: كتاب PDF: 7 أخطاء تقتل حسابك على انستغرام | D27: 0 | E27: جمع بيانات العميل | F27: كتاب مجاني: 5 أسرار لبناء جمهور
A28: 2 — منخفض | B28: Tripwire (تجربة) | C28: دليل بناء الحرية المالية : : كتاب اللكتروني بدون التسويق كارثة تهدر ثروتك المستقبلية | D28: 15,64 | E28: تحويل المتابع لمشتري | F28: كتاب إلكتروني: دليل البدء السريع
A29: 3 — متوسط | B29: Core Offer (العرض الأساسي) | C29: كورس: نظام العميل الأوتوماتيكي — من المتابع للمشتري | D29: 497 | E29: الربح الأساسي | F29: كورس: بناء نظام تسويقي متكامل
A30: 4 — عالي | B30: Premium (مميز) | C30: برنامج VIP: معك شخصياً 8 أسابيع لبناء نظامك كاملاً | D30: 2497 | E30: أعلى ربح لكل عميل | F30: برنامج تدريبي مكثف مع دعم شخصي
A31: 5 — VIP | B31: Continuity (استمرارية) | C31: عضوية شهرية: مجتمع + محتوى حصري + جلسة جماعية أسبوعية | D31: 97 | E31: دخل متكرر شهري | F31: عضوية شهرية: مجتمع خاص + محتوى حصري

Sheet توليد العملاء المحتملين
A1: 🧲 توليد العملاء المحتملين — $100M Leads Framework
A3: 📌 الطرق الأربعة الأساسية (Core Four) لجلب العملاء
A4: الطريقة | B4: النوع | C4: الوصف | D4: خطة التنفيذ | E4: المنصة | F4: الأولوية | G4: الحالة
A5: 1. تواصل دافئ (Warm Outreach) | B5: مجاني | C5: تواصل مباشر مع أشخاص يعرفونك | D5: قائمة 100 شخص → رسالة مخصصة → عرض مساعدة | E5: WhatsApp / Instagram DM | F5: 🔴 عالية | G5: ⬜
A6: 2. محتوى مجاني (Free Content) | B6: مجاني | C6: نشر محتوى قيّم يجذب جمهور جديد | D6: 3-5 منشورات/أسبوع → Reels + Stories + Posts | E6: Instagram / Facebook / YouTube | F6: 🔴 عالية | G6: ⬜
A7: 3. تواصل بارد (Cold Outreach) | B7: مجاني | C7: تواصل مع أشخاص لا يعرفونك | D7: 100 رسالة/يوم → DM مخصص → قيمة أولاً | E7: Instagram DM / Email | F7: 🟡 متوسطة | G7: ⬜
A8: 4. إعلانات مدفوعة (Paid Ads) | B8: مدفوع | C8: إعلانات موجهة لجمهور محدد | D8: حملة تجريبية → اختبار → توسع | E8: Facebook Ads / Instagram Ads | F8: 🟡 متوسطة | G8: ⬜
A10: 🎁 Lead Magnets — مغناطيس العملاء (محتوى مجاني مقابل بيانات العميل)
A11: الرقم | B11: نوع Lead Magnet | C11: العنوان المقترح | D11: الوصف | E11: طريقة التسليم | F11: يجمع
A12: 1 | B12: كتاب إلكتروني مجاني (PDF) | C12: أدخل عنوان الكتاب | D12: دليل مختصر يحل مشكلة محددة | E12: رابط تحميل عبر ManyChat أو البريد | F12: اسم + بريد
A13: 2 | B13: دورة مصغرة مجانية (Mini Course) | C13: أدخل عنوان الدورة | D13: 3-5 فيديوهات قصيرة تعطي نتيجة سريعة | E13: صفحة هبوط → تسجيل → وصول | F13: اسم + بريد + هاتف
A14: 3 | B14: قالب / Template جاهز | C14: أدخل اسم القالب | D14: أداة عملية يستخدمها العميل فوراً | E14: تحميل مباشر أو عبر البريد | F14: اسم + بريد
A15: 4 | B15: ويبينار مجاني (Webinar) | C15: أدخل عنوان الويبينار | D15: جلسة مباشرة تعليمية + عرض في النهاية | E15: Zoom أو صفحة بث مباشر | F15: اسم + بريد + هاتف
A16: 5 | B16: تحدي مجاني (Challenge) | C16: أدخل اسم التحدي | D16: تحدي 5-7 أيام يحقق نتيجة صغيرة | E16: مجموعة Telegram أو WhatsApp | F16: اسم + بريد + هاتف
A18: 🤖 أتمتة ManyChat — سيناريوهات الرد التلقائي
A19: السيناريو | B19: المحفز (Trigger) | C19: الرسالة التلقائية | D19: الإجراء التالي | E19: الهدف
A20: تعليق على بوست | B20: يكتب كلمة محددة في التعليق (مثل: مجاني) | C20: مرحباً! 🎉 شكراً لاهتمامك. الرابط في رسالتك الخاصة | D20: إرسال رابط Lead Magnet + حفظ البيانات | E20: جمع بريد إلكتروني
A21: رسالة مباشرة (DM) | B21: يرسل رسالة أو يبدأ محادثة | C21: أهلاً! كيف أقدر أساعدك؟ هل تبحث عن: 1) كورس 2) كتاب 3) استشارة | D21: توجيه حسب الاختيار → عرض مناسب | E21: تصنيف العميل
A22: Story Reply | B22: يرد على Story | C22: شكراً على ردك! هل تبي تعرف أكثر عن [المنتج]؟ | D22: إرسال معلومات + رابط صفحة هبوط | E22: تحريك العميل للمرحلة التالية
A23: Keyword في DM | B23: يكتب كلمة محددة مثل: سعر / كورس / بداية | C23: إليك تفاصيل [المنتج]: السعر / المميزات / رابط الشراء | D23: متابعة بعد 24 ساعة إذا لم يشتري | E23: تحويل للشراء
A24: بعد الشراء | B24: يكمل عملية الشراء | C24: مبروك! 🎊 تم تسجيلك. إليك رابط الوصول للكورس | D24: إضافة لقائمة العملاء + بدء Onboarding | E24: تجربة عميل ممتازة
A25: testuser@example.com

Sheet Leads CRM


A1: event_name | B1: email | C1: lead_id | D1: source | E1: created_at
A2: lead_created | B2: verify@black4me.com | C2: verify-001 | D2: strict_test | E2: 2026-07-21T07:00:00.000Z

Sheet قمع المبيعات
A1: 🔻 قمع المبيعات — Sales Funnel (رحلة العميل من الاكتشاف إلى الشراء)
A3: 📊 مراحل قمع المبيعات — كل مرحلة = فلتر يقرّب العميل للشراء
A4: المرحلة | B4: الاسم | C4: الهدف | D4: الأدوات | E4: المحتوى / الإجراء | F4: نسبة التحويل المتوقعة | G4: KPI | H4: الحالة
A5: 1️⃣ الوعي | B5: Awareness (اكتشاف) | C5: يعرف أنك موجود | D5: Instagram Reels + Posts + Stories | E5: محتوى تعليمي قيّم + Reels فيروسية | F5: 100% (القاعدة) | G5: مشاهدات + وصول | H5: ⚪ بانتظار البيانات
A6: 2️⃣ الاهتمام | B6: Interest (اهتمام) | C6: يتابعك ويتفاعل | D6: ManyChat + Instagram DM | E6: Lead Magnet مجاني (كتاب/قالب/دورة) | F6: 30-50% | G6: متابعين جدد + تفاعل | H6: ⚪ بانتظار البيانات
A7: 3️⃣ الرغبة | B7: Desire (رغبة) | C7: يريد منتجك | D7: Email + ManyChat Sequences | E7: شهادات عملاء + محتوى قيّم + عروض | F7: 10-20% | G7: نقرات على الروابط | H7: ⚪ بانتظار البيانات
A8: 4️⃣ القرار | B8: Decision (قرار) | C8: مستعد للشراء | D8: صفحة مبيعات + عرض محدود | E8: Grand Slam Offer + ضمان + استعجال | F8: 5-10% | G8: زيارات صفحة المبيعات | H8: ⚪ بانتظار البيانات
A9: 5️⃣ الشراء | B9: Purchase (شراء) | C9: يشتري المنتج | D9: صفحة دفع + ManyChat تأكيد | E9: عملية دفع سهلة + تأكيد فوري | F9: 2-5% | G9: عدد المبيعات + الإيراد | H9: ⚪ بانتظار البيانات
A10: 6️⃣ الولاء | B10: Retention (ولاء) | C10: يشتري مرة أخرى | D10: Email + مجتمع خاص | E10: محتوى حصري + عروض ترقية + Upsell | F10: 20-40% من المشترين | G10: معدل إعادة الشراء | H10: ⚪ بانتظار البيانات
A12: ⚡ تسلسل الإجراءات الأوتوماتيكي — ماذا يحدث في كل مرحلة؟
A13: المحفز (Trigger) | B13: الإجراء التلقائي | C13: الأداة | D13: الوقت | E13: الرسالة / المحتوى
A14: زائر جديد يعلق على بوست | B14: ManyChat يرد + يرسل Lead Magnet | C14: ManyChat | D14: فوري | E14: مرحباً! أرسلنا لك [المنتج المجاني] في الخاص 🎁
A15: يفتح Lead Magnet | B15: Zapier يضيفه لقائمة البريد الإلكتروني | C15: Zapier → Email | D15: فوري | E15: يدخل في سلسلة رسائل ترحيبية
A16: لا يشتري خلال 3 أيام | B16: ManyChat يرسل متابعة | C16: ManyChat | D16: بعد 3 أيام | E16: هل استفدت من [المنتج المجاني]؟ عندي شيء أفضل لك...
A17: ينقر على رابط المنتج | B17: Zapier يصنّفه كـ Hot Lead | C17: Zapier → CRM | D17: فوري | E17: يُنقل لقائمة العملاء المهتمين
A18: يزور صفحة المبيعات ولا يشتري | B18: إعلان إعادة استهداف (Retargeting) | C18: Facebook Ads | D18: بعد 24 ساعة | E18: إعلان مخصص: العرض ينتهي قريباً + شهادة عميل
A19: يشتري | B19: Zapier يؤكد + يسلّم + يبدأ Onboarding | C19: Zapier → Email + ManyChat | D19: فوري | E19: مبروك! 🎊 إليك رابط الوصول + أول خطوة
A20: بعد 7 أيام من الشراء | B20: رسالة متابعة + عرض Upsell | C20: Email + ManyChat | D20: بعد 7 أيام | E20: كيف تقدمك؟ إليك عرض خاص للترقية 🚀

Sheet تسلسل الرسائل
A1: 📨 تسلسل الرسائل — Message Sequences (أتمتة التواصل مع العملاء)
A3: 📱 تسلسل رسائل ManyChat — الرد التلقائي على التعليقات والرسائل
A4: رقم التسلسل | B4: المحفّز (Trigger) | C4: الرسالة الأولى (فورية) | D4: الرسالة الثانية (بعد 5 دقائق) | E4: الرسالة الثالثة (بعد 24 ساعة) | F4: CTA / الإجراء المطلوب | G4: الهدف | H4: ملاحظات
A5: 1 | B5: تعليق على Reel يحتوي كلمة 'كتاب' أو 'مجاني' | C5: مرحباً! 🎉 شكراً على اهتمامك. الكتاب المجاني جاهز لك. أرسل لي 'نعم' وأوصّلك الرابط مباشرة 👇 | D5: ⏰ لاحظت أنك مهتم! الكتاب فيه استراتيجيات غيّرت نتائج +500 شخص. هل أرسل لك الرابط الآن؟ | E5: 📚 آخر تذكير! الكتاب المجاني لا يزال متاح لك. اضغط هنا للتحميل الفوري 👇 [رابط] | F5: تحميل Lead Magnet + جمع الإيميل | G5: توليد عميل محتمل + بناء قائمة | H5: ربط مع Zapier لحفظ البيانات في CRM
A6: 2 | B6: رسالة مباشرة DM تحتوي 'سعر' أو 'كورس' | C6: أهلاً وسهلاً! 💪 أنت في المكان الصحيح. قبل ما أعطيك التفاصيل، خبرني: ايش أكبر تحدي تواجهه في بناء دخلك؟ | D6: شكراً على مشاركتك! ✨ بناءً على اللي قلته، عندي شي يناسبك بالضبط. شوف هالفيديو القصير: [رابط] | E6: 🔥 كثير ناس بنفس وضعك حققوا نتائج خلال 30 يوم. تبي تعرف كيف؟ احجز مكالمة مجانية: [رابط] | F6: حجز مكالمة مجانية / Webinar | G6: تأهيل العميل + نقله للمرحلة التالية | H6: تصنيف العميل حسب نوع التحدي
A7: 3 | B7: تعليق يحتوي 'كيف' أو 'طريقة' | C7: سؤال ممتاز! 🎯 جهّزت لك دليل مجاني يشرح الطريقة خطوة بخطوة. أرسل لي 'أبي الدليل' وأرسله لك 📩 | D7: 💡 الدليل فيه 7 خطوات عملية يستخدمها أنجح رواد الأعمال العرب. جاهز تبدأ؟ | E7: ⚡ أخيراً! الدليل متاح لمدة 48 ساعة فقط. حمّله الآن قبل ينتهي العرض 👇 | F7: تحميل دليل PDF + جمع بيانات | G7: تقديم قيمة مجانية + بناء ثقة | H7: عرض محدود الوقت يخلق إلحاح
A8: 4 | B8: متابعة جديدة للحساب (New Follower) | C8: مرحباً بك في المجتمع! 🙌 أنا [اسمك] وأساعد الناس يبنون مصادر دخل بطريقة ذكية. ايش اللي جذبك للحساب؟ | D8: بالمناسبة! 🎁 عندي هدية ترحيبية — كتاب إلكتروني مجاني عن أسرار بناء الدخل. تبيه؟ | E8: 📊 أكثر من 1000 شخص حمّلوا الكتاب هذا الشهر. لا تفوّت الفرصة! [رابط التحميل] | F8: ترحيب + عرض Lead Magnet | G8: بناء علاقة من أول لحظة | H8: شخّص المتابع الجديد كعميل محتمل
A9: 5 | B9: ردّ على Story يحتوي 'نتائج' أو 'شهادة' | C9: شكراً على رسالتك! 💪 النتائج حقيقية 100%. تبي تعرف كيف تحقق نفس الشي؟ عندي 3 خيارات لك... | D9: الخيارات: 1️⃣ كتاب مجاني (للمبتدئين) 2️⃣ ورشة عمل مباشرة (للجادين) 3️⃣ استشارة شخصية (للي يبون نتائج سريعة) ايش يناسبك؟ | E9: ⏰ المقاعد المتاحة تنفد بسرعة! اختر الخيار اللي يناسبك وأنا أساعدك تبدأ اليوم 🚀 | F9: تصنيف العميل حسب مستوى الجدية | G9: فلترة + توجيه للعرض المناسب | H9: Zapier يسجل الاختيار في CRM
A11: 📧 تسلسل رسائل البريد الإلكتروني — Email Nurture Sequence
A12: اليوم | B12: عنوان الإيميل | C12: نوع المحتوى | D12: الهدف | E12: CTA / الإجراء | F12: النبرة | G12: معدل الفتح المستهدف | H12: ملاحظات
A13: اليوم 0 (فوري) | B13: مرحباً! هديتك المجانية جاهزة 🎁 | C13: تسليم Lead Magnet | D13: تسليم القيمة + بناء أول انطباع | E13: تحميل الكتاب/الدليل المجاني | F13: ودية + حماسية | G13: 0.6 | H13: يُرسل فوراً بعد التسجيل
A14: اليوم 1 | B14: القصة اللي غيّرت كل شي... 📖 | C14: قصة شخصية (Origin Story) | D14: بناء ثقة + مصداقية | E14: اقرأ القصة كاملة | F14: صادقة + ملهمة | G14: 0.45 | H14: قصة التحول الشخصي
A15: اليوم 3 | B15: أكبر 3 أخطاء يرتكبها 90% من الناس ❌ | C15: محتوى تعليمي | D15: إثبات الخبرة + كشف المشاكل | E15: شاهد الفيديو التوضيحي | F15: تعليمية + مباشرة | G15: 0.4 | H15: يكشف نقاط الألم
A16: اليوم 5 | B16: نتائج حقيقية: كيف حقق [اسم] أول 10,000 ريال 💰 | C16: شهادة عميل (Social Proof) | D16: إزالة الشكوك + إثبات النتائج | E16: اقرأ قصة النجاح كاملة | F16: واقعية + محفّزة | G16: 0.42 | H16: استخدم شهادات حقيقية
A17: اليوم 7 | B17: 🔥 عرض خاص لك فقط — ينتهي خلال 48 ساعة | C17: عرض محدود (Urgency) | D17: تحويل العميل المحتمل لمشتري | E17: سجّل الآن بسعر خاص | F17: حاسمة + عاجلة | G17: 0.35 | H17: أول عرض بيع مباشر
A18: اليوم 8 | B18: ⏰ تذكير أخير — العرض ينتهي الليلة! | C18: تذكير + ندرة | D18: استعادة المترددين | E18: آخر فرصة — سجّل الآن | F18: عاجلة + مباشرة | G18: 0.3 | H18: تذكير بانتهاء العرض
A19: اليوم 10 | B19: شكراً لك! + مفاجأة صغيرة 🎉 | C19: محتوى قيمة إضافي | D19: الحفاظ على العلاقة مع غير المشترين | E19: حمّل الهدية الإضافية | F19: شاكرة + كريمة | G19: 0.38 | H19: يبدأ تسلسل جديد للي ما اشتروا
A20: اليوم 14 | B20: ورشة عمل مجانية مباشرة — سجّل مكانك 📺 | C20: دعوة لحدث مباشر | D20: إعادة تنشيط + عرض بديل | E20: احجز مكانك في الورشة | F20: حماسية + تعليمية | G20: 0.35 | H20: للي ما اشتروا الكورس
A22: 📲 تسلسل رسائل WhatsApp / SMS — للمتابعة المباشرة
A23: التوقيت | B23: نوع الرسالة | C23: نص الرسالة | D23: الشرط / المحفّز | E23: CTA | F23: المنصة | G23: الحالة | H23: ملاحظات
A24: فوري | B24: ترحيب | C24: أهلاً [الاسم]! 🙌 شكراً على اهتمامك. رابط الكتاب المجاني: [رابط]. أي سؤال أنا موجود! | D24: بعد تسجيل الإيميل | E24: تحميل + رد | F24: WhatsApp | G24: ⬜ | H24: Zapier يرسل تلقائي
A25: بعد يوم | B25: متابعة | C25: [الاسم] حمّلت الكتاب؟ 📚 أهم فصل هو الثالث — اقرأه أول شي وخبرني رأيك! | D25: إذا ما فتح الرابط | E25: تفاعل + رد | F25: WhatsApp | G25: ⬜ | H25: حسب بيانات الفتح
A26: بعد 3 أيام | B26: قيمة إضافية | C26: 💡 نصيحة سريعة: أنجح الناس يبدأون بعرض واحد قوي بدل 10 عروض ضعيفة. تبي أساعدك تبني عرضك؟ | D26: للجميع | E26: حجز مكالمة | F26: WhatsApp | G26: ⬜ | H26: نصيحة من Hormozi
A27: بعد 5 أيام | B27: عرض | C27: 🔥 [الاسم] عندي عرض خاص لمتابعيني: خصم 40% على كورس [اسم الكورس]. صالح لمدة 48 ساعة فقط! | D27: للمهتمين فقط | E27: رابط الشراء | F27: SMS | G27: ⬜ | H27: فقط للي تفاعلوا
A28: بعد 7 أيام | B28: تذكير أخير | C28: ⏰ آخر يوم للعرض الخاص! [الاسم] لا تفوّت الفرصة. [رابط] 🚀 | D28: للي ما اشتروا | E28: شراء مباشر | F28: SMS | G28: ⬜ | H28: تذكير نهائي
A30: 🔄 تسلسل إعادة التنشيط — لاستعادة العملاء الخاملين
A31: التوقيت | B31: القناة | C31: العنوان / الموضوع | D31: المحتوى | E31: الشرط | F31: الهدف | G31: CTA | H31: ملاحظات
A32: بعد 30 يوم خمول | B32: إيميل | C32: وحشتنا! 💚 وش صار معك؟ | D32: رسالة شخصية + عرض محتوى حصري جديد | E32: ما فتح إيميل لمدة 30 يوم | F32: إعادة التفاعل | G32: شاهد المحتوى الجديد | H32: نبرة ودية وشخصية
A33: بعد 45 يوم خمول | B33: WhatsApp | C33: مرحبا [الاسم]! عندنا تحديثات كبيرة 🚀 | D33: رسالة مباشرة + رابط لمحتوى جديد | E33: لم يتفاعل مع إيميل إعادة التنشيط | F33: محاولة ثانية | G33: شوف التحديثات | H33: أكثر مباشرة
A34: بعد 60 يوم خمول | B34: إيميل | C34: آخر رسالة: عرض خاص لك فقط 🎁 | D34: عرض حصري + خصم خاص للعودة | E34: لا يزال خامل | F34: محاولة أخيرة | G34: استفد من العرض الحصري | H34: إذا ما تفاعل → أرشف
A35: بعد 90 يوم خمول | B35: نظام | C35: نقل للقائمة الخاملة ✋ | D35: أرشفة تلقائية من القائمة النشطة | E35: لم يتفاعل مع أي محاولة | F35: تنظيف القائمة | G35: — | H35: حافظ على نظافة القائمة

Sheet إعدادات الأتمتة
A1: ⚙️ إعدادات الأتمتة — ManyChat + Zapier + أدوات التسويق
A3: 📱 إعدادات ManyChat — الردود التلقائية والتدفقات
A4: رقم التدفق | B4: اسم التدفق (Flow Name) | C4: المحفّز (Trigger) | D4: المنصة | E4: الإجراء التلقائي | F4: البيانات المحفوظة | G4: Zapier Action | H4: الحالة
A5: 1 | B5: ترحيب Lead Magnet | C5: تعليق يحتوي: كتاب / مجاني / أبي | D5: Instagram | E5: إرسال رسالة DM + رابط التحميل تلقائياً | F5: الاسم، اسم المستخدم، الإيميل (بعد الطلب) | G5: → إضافة لقائمة Email + Google Sheets | H5: ⬜ جاهز للربط
A6: 2 | B6: تأهيل العميل | C6: رد DM يحتوي: سعر / كورس / كم | D6: Instagram / Facebook | E6: سؤال تأهيل → تصنيف → توجيه للعرض المناسب | F6: نوع الاهتمام، الميزانية، التحدي | G6: → تحديث CRM + إضافة Tag | H6: ⬜ جاهز للربط
A7: 3 | B7: متابع جديد | C7: متابعة حساب جديدة (New Follower) | D7: Instagram | E7: رسالة ترحيب + عرض هدية مجانية | F7: تاريخ المتابعة، المصدر | G7: → إضافة لقائمة 'متابعين جدد' | H7: ⬜ جاهز للربط
A8: 4 | B8: رد على Story | C8: رد يحتوي: نتائج / كيف / طريقة | D8: Instagram Stories | E8: تسلسل 3 رسائل → خيارات → توجيه | F8: الاختيار (مبتدئ/متوسط/متقدم) | G8: → تصنيف في CRM حسب المستوى | H8: ⬜ جاهز للربط
A9: 5 | B9: حجز مكالمة | C9: ضغط على زر 'احجز مكالمة' | D9: Instagram / الموقع | E9: تأكيد الحجز + تذكيرات تلقائية | F9: التاريخ، الوقت، رقم الهاتف | G9: → Google Calendar + تذكير WhatsApp | H9: ⬜ جاهز للربط
A10: 6 | B10: إعادة استهداف | C10: لم يكمل الشراء (Abandoned) | D10: Facebook Messenger | E10: تذكير + عرض خاص + شهادة عميل | F10: آخر صفحة زارها، المنتج | G10: → Facebook Custom Audience | H10: ⬜ جاهز للربط
H11: ⬜ جاهز للربط
A12: ⚡ إعدادات Zapier — التدفقات الأوتوماتيكية بين المنصات (Zaps)
A13: رقم الـ Zap | B13: اسم الـ Zap | C13: Trigger (المحفّز) | D13: تطبيق المصدر | E13: Action (الإجراء) | F13: تطبيق الوجهة | G13: البيانات المنقولة | H13: الحالة
A14: Zap 1 | B14: Lead Magnet → Email List | C14: ManyChat: جمع إيميل جديد | D14: ManyChat | E14: إضافة جهة اتصال جديدة | F14: Mailchimp / ConvertKit | G14: الاسم، الإيميل، المصدر، التاريخ | H14: ⬜
A15: Zap 2 | B15: Lead Magnet → CRM | C15: ManyChat: عميل محتمل جديد | D15: ManyChat | E15: إنشاء سجل جديد في CRM | F15: Google Sheets / HubSpot | G15: الاسم، الإيميل، الهاتف، المصدر، التصنيف | H15: ⬜
A16: Zap 3 | B16: Form → Email Sequence | C16: موقع: تعبئة نموذج جديد | D16: Typeform / Google Forms | E16: إضافة لتسلسل إيميلات | F16: Mailchimp / ActiveCampaign | G16: الاسم، الإيميل، نوع الاهتمام | H16: ⬜
A17: Zap 4 | B17: Purchase → Thank You | C17: بوابة دفع: عملية شراء ناجحة | D17: Stripe / PayPal | E17: إرسال رسالة شكر + وصول المنتج | F17: Email + WhatsApp | G17: اسم المنتج، المبلغ، الإيميل | H17: ⬜
A18: Zap 5 | B18: Purchase → Upsell | C18: بوابة دفع: شراء منتج معين | D18: Stripe | E18: إضافة لتسلسل Upsell بعد 3 أيام | F18: Mailchimp / ManyChat | G18: المنتج المشترى، التاريخ، القيمة | H18: ⬜
A19: Zap 6 | B19: Webinar Registration | C19: تسجيل في ورشة عمل | D19: Typeform / Calendly | E19: إضافة للقائمة + تذكيرات | F19: Email + Google Calendar | G19: الاسم، الإيميل، تاريخ الورشة | H19: ⬜
A20: Zap 7 | B20: Inactive → Re-engage | C20: إيميل: لم يفتح لمدة 30 يوم | D20: Mailchimp | E20: نقل لتسلسل إعادة التنشيط | F20: ManyChat + WhatsApp | G20: آخر تفاعل، عدد الإيميلات المفتوحة | H20: ⬜
A21: Zap 8 | B21: Review Request | C21: بعد 7 أيام من الشراء | D21: Stripe (Delay) | E21: إرسال طلب تقييم | F21: Email + Google Forms | G21: اسم المنتج، اسم العميل، رابط التقييم | H21: ⬜
H22: ⬜
A23: 🔗 خريطة الربط بين المنصات — كيف تتصل الأدوات ببعضها
A24: المنصة / الأداة | B24: الدور في النظام | C24: تتصل بـ | D24: نوع الاتصال | E24: البيانات المتبادلة | F24: التكلفة الشهرية | G24: البديل المجاني | H24: ⬜
A25: ManyChat | B25: الردود التلقائية + جمع البيانات | C25: Instagram + Facebook + Zapier | D25: API مباشر | E25: بيانات العملاء، التفاعلات، الردود | F25: مجاني (حتى 1000 جهة) / $15+ | G25: — | H25: 🔴 أول شي
A26: Zapier | B26: ربط المنصات + نقل البيانات تلقائياً | C26: كل المنصات | D26: Webhook + API | E26: بيانات العملاء، الأحداث، المحفّزات | F26: مجاني (100 مهمة) / $20+ | G26: Make.com | H26: 🔴 أول شي
A27: Mailchimp / ConvertKit | B27: إدارة قوائم البريد + التسلسلات | C27: Zapier + الموقع | D27: API عبر Zapier | E27: الإيميلات، التسلسلات، الإحصائيات | F27: مجاني (حتى 500) / $13+ | G27: MailerLite | H27: 🟡 ثاني
A28: Google Sheets | B28: CRM بسيط + قاعدة بيانات | C28: Zapier + ManyChat | D28: API عبر Zapier | E28: كل بيانات العملاء المجمّعة | F28: مجاني | G28: — | H28: 🟡 ثاني
A29: Stripe / PayPal | B29: بوابة الدفع + معالجة المبيعات | C29: Zapier + الموقع | D29: Webhook | E29: المبيعات، المبالغ، بيانات العملاء | F29: 2.9% + 30¢ لكل عملية | G29: Tap (للخليج) | H29: 🟢 ثالث
A30: Instagram | B30: المحتوى + التفاعل + جلب العملاء | C30: ManyChat | D30: API (عبر ManyChat) | E30: التعليقات، الرسائل، المتابعين | F30: مجاني | G30: — | H30: 🔴 أول شي
A31: الموقع الإلكتروني | B31: صفحات الهبوط + النماذج + المبيعات | C31: Zapier + Stripe | D31: Forms + Webhook | E31: بيانات النماذج، المبيعات | F31: Carrd: $19/سنة — Systeme.io: مجاني | G31: Systeme.io | H31: 🟡 ثاني
A32: WhatsApp Business | B32: التواصل المباشر + المتابعة | C32: Zapier (عبر Twilio) | D32: API | E32: الرسائل، التأكيدات، التذكيرات | F32: Twilio: ~$0.005/رسالة | G32: WhatsApp Business App (مجاني) | H32: 🟢 ثالث
A34: ✅ قائمة التحقق — خطوات الإعداد بالترتيب
A35: الخطوة | B35: المهمة | C35: الأداة | D35: الوقت المتوقع | E35: التفاصيل | F35: الموارد / الروابط | G35: تم؟ | H35: ملاحظات
A36: 1 | B36: إنشاء حساب ManyChat وربطه بـ Instagram | C36: ManyChat | D36: 30 دقيقة | E36: اذهب لـ manychat.com → سجّل → اربط حساب Instagram Business | F36: manychat.com | G36: ⬜ | H36: يحتاج حساب Instagram Business
A37: 2 | B37: إنشاء حساب Zapier | C37: Zapier | D37: 15 دقيقة | E37: اذهب لـ zapier.com → سجّل بإيميلك → فعّل الحساب | F37: zapier.com | G37: ⬜ | H37: الخطة المجانية كافية للبداية
A38: 3 | B38: إنشاء حساب بريد إلكتروني (Email Marketing) | C38: Mailchimp/ConvertKit | D38: 30 دقيقة | E38: سجّل → أنشئ أول قائمة → صمم إيميل الترحيب | F38: mailchimp.com أو convertkit.com | G38: ⬜ | H38: اختر واحد فقط
A39: 4 | B39: إنشاء Google Sheet كـ CRM | C39: Google Sheets | D39: 20 دقيقة | E39: أنشئ جدول بأعمدة: الاسم، الإيميل، الهاتف، المصدر، التاريخ، التصنيف | F39: sheets.google.com | G39: ⬜ | H39: القالب متوفر في هذا الملف
A40: 5 | B40: بناء أول Flow في ManyChat | C40: ManyChat | D40: 45 دقيقة | E40: Flow: تعليق → رسالة ترحيب → طلب إيميل → إرسال Lead Magnet | F40: — | G40: ⬜ | H40: استخدم القوالب من ورقة تسلسل الرسائل
A41: 6 | B41: ربط ManyChat بـ Zapier (أول Zap) | C41: Zapier + ManyChat | D41: 30 دقيقة | E41: Trigger: ManyChat New Subscriber → Action: Google Sheets Add Row | F41: — | G41: ⬜ | H41: اختبر بإرسال تعليق تجريبي
A42: 7 | B42: إعداد تسلسل الإيميلات | C42: Mailchimp/ConvertKit | D42: 60 دقيقة | E42: أنشئ 8 إيميلات حسب الجدول في ورقة 'تسلسل الرسائل' | F42: — | G42: ⬜ | H42: انسخ المحتوى من الورقة
...

Sheet متابعة الأداء
A1: 📊 متابعة الأداء — مؤشرات الأداء الرئيسية
A3: 📱 القسم الأول: مؤشرات أداء السوشيال ميديا
A4: المؤشر | B4: الهدف الشهري | C4: النتيجة الفعلية | D4: نسبة التحقيق | E4: الحالة | F4: التكرار | G4: المسؤول | H4: ملاحظات
A5: عدد المتابعين الجدد | B5: 500 | C5: 620 | D5: =IF(AND(B5<>"",C5<>""),C5/B5,"") -> 1.24 | E5: =IF(D5="","⚪",IF(D5>=1,"✅ محقق",IF(D5>=0.7,"⚠️ قريب","❌ دون الهدف"))) -> ✅ محقق | F5: شهري
A6: معدل التفاعل على المنشورات | B6: 0.05 | C6: 0.048 | D6: =IF(AND(B6<>"",C6<>""),C6/B6,"") -> 0.96 | E6: =IF(D6="","⚪",IF(D6>=1,"✅ محقق",IF(D6>=0.7,"⚠️ قريب","❌ دون الهدف"))) -> ⚠️ قريب | F6: أسبوعي | H6: إعجابات + تعليقات ÷ متابعين
A7: عدد الرسائل المباشرة الواردة | B7: 80 | C7: 95 | D7: =IF(AND(B7<>"",C7<>""),C7/B7,"") -> 1.1875 | E7: =IF(D7="","⚪",IF(D7>=1,"✅ محقق",IF(D7>=0.7,"⚠️ قريب","❌ دون الهدف"))) -> ✅ محقق | F7: يومي | H7: عبر أتمتة ماني شات
A8: عدد التعليقات بكلمة مفتاحية | B8: 150 | C8: 210 | D8: =IF(AND(B8<>"",C8<>""),C8/B8,"") -> 1.4 | E8: =IF(D8="","⚪",IF(D8>=1,"✅ محقق",IF(D8>=0.7,"⚠️ قريب","❌ دون الهدف"))) -> ✅ محقق | F8: يومي | H8: تعليقات تحتوي كلمة مفتاحية محددة
A9: معدل النقر على الرابط الحيوي | B9: 0.03 | C9: 0.025 | D9: =IF(AND(B9<>"",C9<>""),C9/B9,"") -> 0.83333333 | E9: =IF(D9="","⚪",IF(D9>=1,"✅ محقق",IF(D9>=0.7,"⚠️ قريب","❌ دون الهدف"))) -> ⚠️ قريب | F9: أسبوعي | H9: رابط صفحة الهبوط
A10: عدد مشاهدات الريلز والقصص | B10: 15000 | C10: 18500 | D10: =IF(AND(B10<>"",C10<>""),C10/B10,"") -> 1.2333333 | E10: =IF(D10="","⚪",IF(D10>=1,"✅ محقق",IF(D10>=0.7,"⚠️ قريب","❌ دون الهدف"))) -> ✅ محقق | F10: يومي
A11: تكلفة اكتساب العميل المحتمل | B11: 25 | C11: 31 | D11: =IF(AND(B11<>"",C11<>""),C11/B11,"") -> 1.24 | E11: =IF(D11="","⚪",IF(D11>=1,"✅ محقق",IF(D11>=0.7,"⚠️ قريب","❌ دون الهدف"))) -> ✅ محقق | F11: شهري | H11: إنفاق ÷ عملاء محتملين
A12: معدل التحويل من متابع لعميل | B12: 0.02 | C12: 0.018 | D12: =IF(AND(B12<>"",C12<>""),C12/B12,"") -> 0.9 | E12: =IF(D12="","⚪",IF(D12>=1,"✅ محقق",IF(D12>=0.7,"⚠️ قريب","❌ دون الهدف"))) -> ⚠️ قريب | F12: شهري
A14: 🌐 القسم الثاني: مؤشرات أداء الموقع الإلكتروني
A15: المؤشر | B15: الهدف الشهري | C15: النتيجة الفعلية | D15: نسبة التحقيق | E15: الحالة | F15: التكرار | G15: المسؤول | H15: ملاحظات
A16: عدد زوار الموقع | B16: 3000 | C16: 2750 | D16: =IF(AND(B16<>"",C16<>""),C16/B16,"") -> 0.91666667 | E16: =IF(D16="","⚪",IF(D16>=1,"✅ محقق",IF(D16>=0.7,"⚠️ قريب","❌ دون الهدف"))) -> ⚠️ قريب | F16: شهري
A17: معدل الارتداد | B17: 0.38 | C17: 0.42 | D17: =IF(AND(B17<>"",C17<>""),C17/B17,"") -> 1.1052632 | E17: =IF(D17="","⚪",IF(D17>=1,"✅ محقق",IF(D17>=0.7,"⚠️ قريب","❌ دون الهدف"))) -> ✅ محقق | F17: أسبوعي | H17: النسبة المثالية أقل من 40%
A18: عدد تسجيلات النماذج | B18: 120 | C18: 98 | D18: =IF(AND(B18<>"",C18<>""),C18/B18,"") -> 0.81666667 | E18: =IF(D18="","⚪",IF(D18>=1,"✅ محقق",IF(D18>=0.7,"⚠️ قريب","❌ دون الهدف"))) -> ⚠️ قريب | F18: يومي | H18: نماذج جمع البريد الإلكتروني
A19: معدل التحويل من زائر لمسجل | B19: 0.04 | C19: 0.036 | D19: =IF(AND(B19<>"",C19<>""),C19/B19,"") -> 0.9 | E19: =IF(D19="","⚪",IF(D19>=1,"✅ محقق",IF(D19>=0.7,"⚠️ قريب","❌ دون الهدف"))) -> ⚠️ قريب | F19: شهري | H19: تسجيلات ÷ زوار
A20: متوسط وقت البقاء في الصفحة | B20: 180 | C20: 210 | D20: =IF(AND(B20<>"",C20<>""),C20/B20,"") -> 1.1666667 | E20: =IF(D20="","⚪",IF(D20>=1,"✅ محقق",IF(D20>=0.7,"⚠️ قريب","❌ دون الهدف"))) -> ✅ محقق | F20: أسبوعي | H20: كلما زاد الوقت كان أفضل
A21: عدد النقرات على زر الشراء | B21: 85 | C21: 67 | D21: =IF(AND(B21<>"",C21<>""),C21/B21,"") -> 0.78823529 | E21: =IF(D21="","⚪",IF(D21>=1,"✅ محقق",IF(D21>=0.7,"⚠️ قريب","❌ دون الهدف"))) -> ⚠️ قريب | F21: يومي
A22: عدد عمليات الشراء المكتملة | B22: 18 | C22: 14 | D22: =IF(AND(B22<>"",C22<>""),C22/B22,"") -> 0.77777778 | E22: =IF(D22="","⚪",IF(D22>=1,"✅ محقق",IF(D22>=0.7,"⚠️ قريب","❌ دون الهدف"))) -> ⚠️ قريب | F22: يومي
A24: 📧 القسم الثالث: مؤشرات أداء البريد الإلكتروني
A25: المؤشر | B25: الهدف الشهري | C25: النتيجة الفعلية | D25: نسبة التحقيق | E25: الحالة | F25: التكرار | G25: المسؤول | H25: ملاحظات
A26: عدد المشتركين الجدد بالقائمة البريدية | B26: 200 | C26: 235 | D26: =IF(AND(B26<>"",C26<>""),C26/B26,"") -> 1.175 | E26: =IF(D26="","⚪",IF(D26>=1,"✅ محقق",IF(D26>=0.7,"⚠️ قريب","❌ دون الهدف"))) -> ✅ محقق | F26: شهري
A27: معدل فتح الرسائل البريدية | B27: 0.25 | C27: 0.28 | D27: =IF(AND(B27<>"",C27<>""),C27/B27,"") -> 1.12 | E27: =IF(D27="","⚪",IF(D27>=1,"✅ محقق",IF(D27>=0.7,"⚠️ قريب","❌ دون الهدف"))) -> ✅ محقق | F27: لكل حملة | H27: المعدل المثالي 20-30%
A28: معدل النقر داخل البريد | B28: 0.04 | C28: 0.035 | D28: =IF(AND(B28<>"",C28<>""),C28/B28,"") -> 0.875 | E28: =IF(D28="","⚪",IF(D28>=1,"✅ محقق",IF(D28>=0.7,"⚠️ قريب","❌ دون الهدف"))) -> ⚠️ قريب | F28: لكل حملة | H28: المعدل المثالي 3-5%
A29: معدل إلغاء الاشتراك | B29: 0.005 | C29: 0.003 | D29: =IF(AND(B29<>"",C29<>""),C29/B29,"") -> 0.6 | E29: =IF(D29="","⚪",IF(D29>=1,"✅ محقق",IF(D29>=0.7,"⚠️ قريب","❌ دون الهدف"))) -> ❌ دون الهدف | F29: شهري | H29: يجب أن يكون أقل من 0.5%
A30: عدد الردود على الرسائل | B30: 30 | C30: 44 | D30: =IF(AND(B30<>"",C30<>""),C30/B30,"") -> 1.4666667 | E30: =IF(D30="","⚪",IF(D30>=1,"✅ محقق",IF(D30>=0.7,"⚠️ قريب","❌ دون الهدف"))) -> ✅ محقق | F30: أسبوعي | H30: مؤشر على جودة المحتوى
A31: معدل التحويل من بريد لشراء | B31: 0.025 | C31: 0.02 | D31: =IF(AND(B31<>"",C31<>""),C31/B31,"") -> 0.8 | E31: =IF(D31="","⚪",IF(D31>=1,"✅ محقق",IF(D31>=0.7,"⚠️ قريب","❌ دون الهدف"))) -> ⚠️ قريب | F31: شهري
A32: إجمالي الإيرادات من حملات البريد | B32: 5000 | C32: 3976 | D32: =IF(AND(B32<>"",C32<>""),C32/B32,"") -> 0.7952 | E32: =IF(D32="","⚪",IF(D32>=1,"✅ محقق",IF(D32>=0.7,"⚠️ قريب","❌ دون الهدف"))) -> ⚠️ قريب | F32: شهري
A34: 💰 القسم الرابع: مؤشرات المبيعات والإيرادات
A35: المؤشر | B35: الهدف الشهري | C35: النتيجة الفعلية | D35: نسبة التحقيق | E35: الحالة | F35: التكرار | G35: المسؤول | H35: ملاحظات
A36: إجمالي الإيرادات الشهرية | B36: 15000 | C36: 13916 | D36: =IF(AND(B36<>"",C36<>""),C36/B36,"") -> 0.92773333 | E36: =IF(D36="","⚪",IF(D36>=1,"✅ محقق",IF(D36>=0.7,"⚠️ قريب","❌ دون الهدف"))) -> ⚠️ قريب | F36: شهري | H36: جميع المنتجات
A37: عدد المبيعات الجديدة | B37: 30 | C37: 28 | D37: =IF(AND(B37<>"",C37<>""),C37/B37,"") -> 0.93333333 | E37: =IF(D37="","⚪",IF(D37>=1,"✅ محقق",IF(D37>=0.7,"⚠️ قريب","❌ دون الهدف"))) -> ⚠️ قريب | F37: شهري | H37: دورات + كتب إلكترونية
A38: متوسط قيمة الطلب الواحد | B38: 497 | C38: =C36/C37 -> 497 | D38: =IF(AND(B38<>"",C38<>""),C38/B38,"") -> 1 | E38: =IF(D38="","⚪",IF(D38>=1,"✅ محقق",IF(D38>=0.7,"⚠️ قريب","❌ دون الهدف"))) -> ✅ محقق | F38: شهري | H38: إيرادات ÷ عدد الطلبات
A39: معدل التحويل الكلي للقمع | B39: 0.03 | C39: 0.025 | D39: =IF(AND(B39<>"",C39<>""),C39/B39,"") -> 0.83333333 | E39: =IF(D39="","⚪",IF(D39>=1,"✅ محقق",IF(D39>=0.7,"⚠️ قريب","❌ دون الهدف"))) -> ⚠️ قريب | F39: شهري | H39: مشترين ÷ عملاء محتملين
A40: قيمة العميل مدى الحياة | B40: 1200 | C40: 950 | D40: =IF(AND(B40<>"",C40<>""),C40/B40,"") -> 0.79166667 | E40: =IF(D40="","⚪",IF(D40>=1,"✅ محقق",IF(D40>=0.7,"⚠️ قريب","❌ دون الهدف"))) -> ⚠️ قريب | F40: ربع سنوي | H40: متوسط إنفاق العميل الكلي
A41: عائد الاستثمار التسويقي | B41: 3 | C41: =IFERROR((C36-2000)/2000,0) -> 5.958 | D41: =IF(AND(B41<>"",C41<>""),C41/B41,"") -> 1.986 | E41: =IF(D41="","⚪",IF(D41>=1,"✅ محقق",IF(D41>=0.7,"⚠️ قريب","❌ دون الهدف"))) -> ✅ محقق | F41: شهري | H41: (إيرادات - تكاليف) ÷ تكاليف
A42: عدد العملاء المتكررين | B42: 8 | C42: 6 | D42: =IF(AND(B42<>"",C42<>""),C42/B42,"") -> 0.75 | E42: =IF(D42="","⚪",IF(D42>=1,"✅ محقق",IF(D42>=0.7,"⚠️ قريب","❌ دون الهدف"))) -> ⚠️ قريب | F42: شهري | H42: عملاء اشتروا أكثر من مرة
A43: معدل استرداد الأموال | B43: 0.03 | C43: 0.02 | D43: =IF(AND(B43<>"",C43<>""),C43/B43,"") -> 0.66666667 | E43: =IF(D43="","⚪",IF(D43>=1,"✅ محقق",IF(D43>=0.7,"⚠️ قريب","❌ دون الهدف"))) -> ❌ دون الهدف | F43: شهري | H43: يجب أن يكون أقل من 5%
A45: 📈 ملخص الأداء العام
...
